Workbook

Sheet How to Schedule
A1: DK CRICKET OPS — SIMPLE GROUND SCHEDULING
A3: Default schedule | B3: AK Club DY Patil Ground has one row for every Saturday and Sunday through 28-Feb-2027.
A4: Collaboration ground needed? | B4: When you book MCG or Lords of Maval, insert a new row under that date, copy an existing schedule row, and change Ground to MCG Ground or Lords of Maval.
A5: Fixture entry | B5: For leather matches, type Team A vs Team B into one leather slot cell. Keep the exact format with spaces around 'vs'.
A6: Payments | B6: The Leather Payment Tracker splits Team A and Team B automatically. Select Pending or Paid separately when each team's GPay payment arrives.
A7: Important | B7: Do not type a collaboration match into the AK Club row unless it is actually happening at AK Club DY Patil Ground.

Sheet Ground Schedule
A1: DK CRICKET OPS — WEEKEND GROUND & MATCH SCHEDULE
A2: Default view: AK Club DY Patil Ground is pre-listed every Saturday/Sunday through 28-Feb-2027. MCG and Lords of Maval appear only when an existing booking/match is recorded; add a row for either collaboration ground only when needed. Enter leather fixtures as Team A vs Team B.
A4: Date | B4: Day | C4: Ground | D4: 07:00 AM Slot | E4: 09:00 AM Tennis Slot | F4: Leather Slot | G4: 10:30 AM Slot | H4: 12:00 PM Slot | I4: 02:00 PM Slot | J4: 03:30 PM Slot | K4: Booking / Notes | L4: Ground Status | M4: CCL | N4: Winter Championship | O4: Pink County Cup | P4: Corporate Strikers | Q4: AK Club Quadrangular | R4: Payment Received — Team Name(s)
A5: 46298 | B5: Saturday | C5: AK Club DY Patil Ground | L5: Available | M5: Rising Champions | N5: HITMAN SPORTS S4 | O5: Shivas Smashers | P5: Pune Titans | Q5: Team Aristo
A6: 46298 | B6: Saturday | C6: MCG Ground | E6: Parents Pay vs Decisive XI | G6: Ktown Night Riders vs Western Warriors | L6: Scheduled | M6: Om Cricket Club (Pune) | N6: Batboys | O6: Batboys | P6: Batboys | Q6: Deccan Shiledars
A7: 46298 | B7: Saturday | C7: Lords of Maval | D7: Booked CT1 Bhushan | E7: EPAM CC | G7: Team Aristo vs Scoring Swords | I7: Hitman Sports vs Boundaryline | K7: Booked CT1 Bhushan | L7: Booked | M7: Pattern Strikers | N7: Boundary Line Elite - XI | O7: Black Caps 11 | P7: BR Bulls | Q7: Phoenix Risers
A8: 46299 | B8: Sunday | C8: AK Club DY Patil Ground | L8: Available | M8: SCC United | N8: Scoring Swords (Pune) | P8: Royals XI
A9: 46299 | B9: Sunday | C9: Lords of Maval | D9: Booked LR Arezo Kings | E9: EPAM CC | G9: Titan Wolves vs Royal Strikers | I9: Practice Match | K9: Booked LR Arezo Kings | L9: Booked | M9: Royal Strikers -2024 | N9: Royals XI | O9: Topguns Cricket Club | P9: Royal Strikers -2024 | Q9: Titan Wolves
A10: 46305 | B10: Saturday | C10: AK Club DY Patil Ground | D10: Booked DC United | E10: EPAM CC | G10: Phoenix Risers vs Overtime Hitters | I10: Batboys vs Boundary Line | K10: Booked DC United | L10: Booked | M10: Vajra Vikings | N10: Top Gun Mavericks | P10: STALLION STRIKERS
A11: 46305 | B11: Saturday | C11: MCG Ground | G11: Bharam 11 vs Scoring Swords | L11: Scheduled
A12: 46306 | B12: Sunday | C12: AK Club DY Patil Ground | D12: Booked LR Arezo Kings | G12: Decisive 11 vs Bravebulls | I12: Boundary Line vs Royals 11 | K12: Booked LR Arezo Kings | L12: Booked
A13: 46306 | B13: Sunday | C13: MCG Ground | G13: Sangha vs University | L13: Scheduled
A14: 46306 | B14: Sunday | C14: Lords of Maval | G14: Microland vs Strikeforge | L14: Scheduled
A15: 46312 | B15: Saturday | C15: AK Club DY Patil Ground | L15: Available
A16: 46312 | B16: Saturday | C16: Lords of Maval | D16: Booked DC United | G16: Strikeforge vs Township (P) | I16: TopGun Mavericks vs Scoring Swords | K16: Booked DC United | L16: Booked
A17: 46313 | B17: Sunday | C17: AK Club DY Patil Ground | L17: Available
A18: 46313 | B18: Sunday | C18: Lords of Maval | D18: Booked CT1 Bhushan | G18: SJ Warriors vs Royal Strikers | I18: Team Aristo vs Boundary Line | K18: Booked CT1 Bhushan | L18: Booked
A19: 46319 | B19: Saturday | C19: AK Club DY Patil Ground | L19: Available
A20: 46319 | B20: Saturday | C20: Lords of Maval | D20: Booked CT1 Bhushan | G20: Team Aristo vs Phoenix Risers | I20: Sangha vs BR Bulls — Semi | K20: Booked CT1 Bhushan | L20: Booked
A21: 46320 | B21: Sunday | C21: AK Club DY Patil Ground | L21: Available
A22: 46320 | B22: Sunday | C22: Lords of Maval | D22: Booked DC United | G22: Pattern Strikers vs Titan Wolves | I22: Black Caps vs Topguns Cricket Club | K22: Booked DC United | L22: Booked
A23: 46326 | B23: Saturday | C23: AK Club DY Patil Ground | L23: Available
A24: 46326 | B24: Saturday | C24: Lords of Maval | D24: Booked DC United | G24: OM Cricket Club vs Rising Champions | I24: Vajra Vikings vs SCC United | K24: Booked DC United | L24: Booked
A25: 46327 | B25: Sunday | C25: AK Club DY Patil Ground | L25: Available
A26: 46327 | B26: Sunday | C26: Lords of Maval | D26: Available | G26: Team Aristo vs Hitman Sports | I26: Phoenix Risers vs Deccan Shiledar | K26: Available | L26: Available
A27: 46333 | B27: Saturday | C27: AK Club DY Patil Ground | L27: Available
A28: 46333 | B28: Saturday | C28: Lords of Maval | D28: Available | G28: Boundary Line vs TopGun Mavericks | I28: Topguns Cricket Club vs Batboys | K28: Available | L28: Available
A29: 46334 | B29: Sunday | C29: AK Club DY Patil Ground | L29: Available
A30: 46334 | B30: Sunday | C30: Lords of Maval | D30: Available | I30: Scoring Swords vs Royals XI | K30: Available | L30: Available
A31: 46340 | B31: Saturday | C31: AK Club DY Patil Ground | L31: Available
A32: 46340 | B32: Saturday | C32: Lords of Maval | D32: Available | G32: Scoring Swords vs Hitman Sports | I32: Titan Wolves vs OM Cricket Club | K32: Available | L32: Available
A33: 46341 | B33: Sunday | C33: AK Club DY Patil Ground | L33: Available
A34: 46341 | B34: Sunday | C34: Lords of Maval | D34: Available | I34: Pattern Strikers vs SCC United | K34: Available | L34: Available
A35: 46347 | B35: Saturday | C35: AK Club DY Patil Ground | L35: Available
A36: 46347 | B36: Saturday | C36: Lords of Maval | D36: Available | G36: Scoring Swords vs Boundary Line | I36: Vajra Vikings vs Titan Wolves | K36: Available | L36: Available
A37: 46348 | B37: Sunday | C37: AK Club DY Patil Ground | L37: Available
A38: 46348 | B38: Sunday | C38: Lords of Maval | D38: Available | I38: Royal Strikers vs Rising Champions | K38: Available | L38: Available
A39: 46354 | B39: Saturday | C39: AK Club DY Patil Ground | L39: Available
A40: 46354 | B40: Saturday | C40: Lords of Maval | D40: Available | I40: Team Aristo vs TopGun Mavericks | K40: Available | L40: Available
A41: 46355 | B41: Sunday | C41: AK Club DY Patil Ground | L41: Available
...

Sheet Leather Payment Tracker
A1: DK CRICKET OPS — AUTO-LINKED MATCH PAYMENT TRACKER
A2: Enter each match in Ground Schedule as Team A vs Team B in a slot (columns F:J). Every match appears here automatically with separate payment dropdowns for both teams. 3 matches = 6 team payment markings; 2 matches = 4 markings.
A3: Match Date | B3: Ground | C3: Time Slot | D3: Fixture (linked) | E3: Team A | F3: Team A Payment | G3: Team B | H3: Team B Payment | I3: Overall Status | J3: Payment Notes
A4: =IF(OR('Ground Schedule'!A5="",'Ground Schedule'!F5=""),"",'Ground Schedule'!A5) | B4: =IF(A4="","",'Ground Schedule'!C5) | C4: =IF(A4="","",'Ground Schedule'!F$4) | D4: =IF(A4="","",'Ground Schedule'!F5) | E4: =IFERROR(TRIM(LEFT(D4,SEARCH(" vs ",D4)-1)),"") | G4: =IFERROR(TRIM(MID(D4,SEARCH(" vs ",D4)+4,LEN(D4))),"") | I4: =IF(OR(E4="",G4=""),"",IF(AND(F4="Paid",H4="Paid"),"Both Paid",IF(AND(OR(F4="Pending",F4=""),OR(H4="Pending",H4="")),"Both Pending",IF(AND(F4="Not Applicable",H4="Not Applicable"),"Not Applicable",IF(OR(F4="Paid",H4="Paid"),"Partially Paid","Pending")))))
A5: =IF(OR('Ground Schedule'!A5="",'Ground Schedule'!G5=""),"",'Ground Schedule'!A5) | B5: =IF(A5="","",'Ground Schedule'!C5) | C5: =IF(A5="","",'Ground Schedule'!G$4) | D5: =IF(A5="","",'Ground Schedule'!G5) | E5: =IFERROR(TRIM(LEFT(D5,SEARCH(" vs ",D5)-1)),"") | G5: =IFERROR(TRIM(MID(D5,SEARCH(" vs ",D5)+4,LEN(D5))),"") | I5: =IF(OR(E5="",G5=""),"",IF(AND(F5="Paid",H5="Paid"),"Both Paid",IF(AND(OR(F5="Pending",F5=""),OR(H5="Pending",H5="")),"Both Pending",IF(AND(F5="Not Applicable",H5="Not Applicable"),"Not Applicable",IF(OR(F5="Paid",H5="Paid"),"Partially Paid","Pending")))))
A6: =IF(OR('Ground Schedule'!A5="",'Ground Schedule'!H5=""),"",'Ground Schedule'!A5) | B6: =IF(A6="","",'Ground Schedule'!C5) | C6: =IF(A6="","",'Ground Schedule'!H$4) | D6: =IF(A6="","",'Ground Schedule'!H5) | E6: =IFERROR(TRIM(LEFT(D6,SEARCH(" vs ",D6)-1)),"") | G6: =IFERROR(TRIM(MID(D6,SEARCH(" vs ",D6)+4,LEN(D6))),"") | I6: =IF(OR(E6="",G6=""),"",IF(AND(F6="Paid",H6="Paid"),"Both Paid",IF(AND(OR(F6="Pending",F6=""),OR(H6="Pending",H6="")),"Both Pending",IF(AND(F6="Not Applicable",H6="Not Applicable"),"Not Applicable",IF(OR(F6="Paid",H6="Paid"),"Partially Paid","Pending")))))
A7: =IF(OR('Ground Schedule'!A5="",'Ground Schedule'!I5=""),"",'Ground Schedule'!A5) | B7: =IF(A7="","",'Ground Schedule'!C5) | C7: =IF(A7="","",'Ground Schedule'!I$4) | D7: =IF(A7="","",'Ground Schedule'!I5) | E7: =IFERROR(TRIM(LEFT(D7,SEARCH(" vs ",D7)-1)),"") | G7: =IFERROR(TRIM(MID(D7,SEARCH(" vs ",D7)+4,LEN(D7))),"") | I7: =IF(OR(E7="",G7=""),"",IF(AND(F7="Paid",H7="Paid"),"Both Paid",IF(AND(OR(F7="Pending",F7=""),OR(H7="Pending",H7="")),"Both Pending",IF(AND(F7="Not Applicable",H7="Not Applicable"),"Not Applicable",IF(OR(F7="Paid",H7="Paid"),"Partially Paid","Pending")))))
A8: =IF(OR('Ground Schedule'!A5="",'Ground Schedule'!J5=""),"",'Ground Schedule'!A5) | B8: =IF(A8="","",'Ground Schedule'!C5) | C8: =IF(A8="","",'Ground Schedule'!J$4) | D8: =IF(A8="","",'Ground Schedule'!J5) | E8: =IFERROR(TRIM(LEFT(D8,SEARCH(" vs ",D8)-1)),"") | G8: =IFERROR(TRIM(MID(D8,SEARCH(" vs ",D8)+4,LEN(D8))),"") | I8: =IF(OR(E8="",G8=""),"",IF(AND(F8="Paid",H8="Paid"),"Both Paid",IF(AND(OR(F8="Pending",F8=""),OR(H8="Pending",H8="")),"Both Pending",IF(AND(F8="Not Applicable",H8="Not Applicable"),"Not Applicable",IF(OR(F8="Paid",H8="Paid"),"Partially Paid","Pending")))))
A9: =IF(OR('Ground Schedule'!A6="",'Ground Schedule'!F6=""),"",'Ground Schedule'!A6) | B9: =IF(A9="","",'Ground Schedule'!C6) | C9: =IF(A9="","",'Ground Schedule'!F$4) | D9: =IF(A9="","",'Ground Schedule'!F6) | E9: =IFERROR(TRIM(LEFT(D9,SEARCH(" vs ",D9)-1)),"") | G9: =IFERROR(TRIM(MID(D9,SEARCH(" vs ",D9)+4,LEN(D9))),"") | I9: =IF(OR(E9="",G9=""),"",IF(AND(F9="Paid",H9="Paid"),"Both Paid",IF(AND(OR(F9="Pending",F9=""),OR(H9="Pending",H9="")),"Both Pending",IF(AND(F9="Not Applicable",H9="Not Applicable"),"Not Applicable",IF(OR(F9="Paid",H9="Paid"),"Partially Paid","Pending")))))
A10: =IF(OR('Ground Schedule'!A6="",'Ground Schedule'!G6=""),"",'Ground Schedule'!A6) -> 46298 | B10: =IF(A10="","",'Ground Schedule'!C6) -> MCG Ground | C10: =IF(A10="","",'Ground Schedule'!G$4) -> 10:30 AM Slot | D10: =IF(A10="","",'Ground Schedule'!G6) -> Ktown Night Riders vs Western Warriors | E10: =IFERROR(TRIM(LEFT(D10,SEARCH(" vs ",D10)-1)),"") -> Ktown Night Riders | G10: =IFERROR(TRIM(MID(D10,SEARCH(" vs ",D10)+4,LEN(D10))),"") -> Western Warriors | I10: =IF(OR(E10="",G10=""),"",IF(AND(F10="Paid",H10="Paid"),"Both Paid",IF(AND(OR(F10="Pending",F10=""),OR(H10="Pending",H10="")),"Both Pending",IF(AND(F10="Not Applicable",H10="Not Applicable"),"Not Applicable",IF(OR(F10="Paid",H10="Paid"),"Partially Paid","Pending"))))) -> Both Pending
A11: =IF(OR('Ground Schedule'!A6="",'Ground Schedule'!H6=""),"",'Ground Schedule'!A6) | B11: =IF(A11="","",'Ground Schedule'!C6) | C11: =IF(A11="","",'Ground Schedule'!H$4) | D11: =IF(A11="","",'Ground Schedule'!H6) | E11: =IFERROR(TRIM(LEFT(D11,SEARCH(" vs ",D11)-1)),"") | G11: =IFERROR(TRIM(MID(D11,SEARCH(" vs ",D11)+4,LEN(D11))),"") | I11: =IF(OR(E11="",G11=""),"",IF(AND(F11="Paid",H11="Paid"),"Both Paid",IF(AND(OR(F11="Pending",F11=""),OR(H11="Pending",H11="")),"Both Pending",IF(AND(F11="Not Applicable",H11="Not Applicable"),"Not Applicable",IF(OR(F11="Paid",H11="Paid"),"Partially Paid","Pending")))))
A12: =IF(OR('Ground Schedule'!A6="",'Ground Schedule'!I6=""),"",'Ground Schedule'!A6) | B12: =IF(A12="","",'Ground Schedule'!C6) | C12: =IF(A12="","",'Ground Schedule'!I$4) | D12: =IF(A12="","",'Ground Schedule'!I6) | E12: =IFERROR(TRIM(LEFT(D12,SEARCH(" vs ",D12)-1)),"") | G12: =IFERROR(TRIM(MID(D12,SEARCH(" vs ",D12)+4,LEN(D12))),"") | I12: =IF(OR(E12="",G12=""),"",IF(AND(F12="Paid",H12="Paid"),"Both Paid",IF(AND(OR(F12="Pending",F12=""),OR(H12="Pending",H12="")),"Both Pending",IF(AND(F12="Not Applicable",H12="Not Applicable"),"Not Applicable",IF(OR(F12="Paid",H12="Paid"),"Partially Paid","Pending")))))
A13: =IF(OR('Ground Schedule'!A6="",'Ground Schedule'!J6=""),"",'Ground Schedule'!A6) | B13: =IF(A13="","",'Ground Schedule'!C6) | C13: =IF(A13="","",'Ground Schedule'!J$4) | D13: =IF(A13="","",'Ground Schedule'!J6) | E13: =IFERROR(TRIM(LEFT(D13,SEARCH(" vs ",D13)-1)),"") | G13: =IFERROR(TRIM(MID(D13,SEARCH(" vs ",D13)+4,LEN(D13))),"") | I13: =IF(OR(E13="",G13=""),"",IF(AND(F13="Paid",H13="Paid"),"Both Paid",IF(AND(OR(F13="Pending",F13=""),OR(H13="Pending",H13="")),"Both Pending",IF(AND(F13="Not Applicable",H13="Not Applicable"),"Not Applicable",IF(OR(F13="Paid",H13="Paid"),"Partially Paid","Pending")))))
A14: =IF(OR('Ground Schedule'!A7="",'Ground Schedule'!F7=""),"",'Ground Schedule'!A7) | B14: =IF(A14="","",'Ground Schedule'!C7) | C14: =IF(A14="","",'Ground Schedule'!F$4) | D14: =IF(A14="","",'Ground Schedule'!F7) | E14: =IFERROR(TRIM(LEFT(D14,SEARCH(" vs ",D14)-1)),"") | G14: =IFERROR(TRIM(MID(D14,SEARCH(" vs ",D14)+4,LEN(D14))),"") | I14: =IF(OR(E14="",G14=""),"",IF(AND(F14="Paid",H14="Paid"),"Both Paid",IF(AND(OR(F14="Pending",F14=""),OR(H14="Pending",H14="")),"Both Pending",IF(AND(F14="Not Applicable",H14="Not Applicable"),"Not Applicable",IF(OR(F14="Paid",H14="Paid"),"Partially Paid","Pending")))))
A15: =IF(OR('Ground Schedule'!A7="",'Ground Schedule'!G7=""),"",'Ground Schedule'!A7) -> 46298 | B15: =IF(A15="","",'Ground Schedule'!C7) -> Lords of Maval | C15: =IF(A15="","",'Ground Schedule'!G$4) -> 10:30 AM Slot | D15: =IF(A15="","",'Ground Schedule'!G7) -> Team Aristo vs Scoring Swords | E15: =IFERROR(TRIM(LEFT(D15,SEARCH(" vs ",D15)-1)),"") -> Team Aristo | G15: =IFERROR(TRIM(MID(D15,SEARCH(" vs ",D15)+4,LEN(D15))),"") -> Scoring Swords | I15: =IF(OR(E15="",G15=""),"",IF(AND(F15="Paid",H15="Paid"),"Both Paid",IF(AND(OR(F15="Pending",F15=""),OR(H15="Pending",H15="")),"Both Pending",IF(AND(F15="Not Applicable",H15="Not Applicable"),"Not Applicable",IF(OR(F15="Paid",H15="Paid"),"Partially Paid","Pending"))))) -> Both Pending
A16: =IF(OR('Ground Schedule'!A7="",'Ground Schedule'!H7=""),"",'Ground Schedule'!A7) | B16: =IF(A16="","",'Ground Schedule'!C7) | C16: =IF(A16="","",'Ground Schedule'!H$4) | D16: =IF(A16="","",'Ground Schedule'!H7) | E16: =IFERROR(TRIM(LEFT(D16,SEARCH(" vs ",D16)-1)),"") | G16: =IFERROR(TRIM(MID(D16,SEARCH(" vs ",D16)+4,LEN(D16))),"") | I16: =IF(OR(E16="",G16=""),"",IF(AND(F16="Paid",H16="Paid"),"Both Paid",IF(AND(OR(F16="Pending",F16=""),OR(H16="Pending",H16="")),"Both Pending",IF(AND(F16="Not Applicable",H16="Not Applicable"),"Not Applicable",IF(OR(F16="Paid",H16="Paid"),"Partially Paid","Pending")))))
A17: =IF(OR('Ground Schedule'!A7="",'Ground Schedule'!I7=""),"",'Ground Schedule'!A7) -> 46298 | B17: =IF(A17="","",'Ground Schedule'!C7) -> Lords of Maval | C17: =IF(A17="","",'Ground Schedule'!I$4) -> 02:00 PM Slot | D17: =IF(A17="","",'Ground Schedule'!I7) -> Hitman Sports vs Boundaryline | E17: =IFERROR(TRIM(LEFT(D17,SEARCH(" vs ",D17)-1)),"") -> Hitman Sports | G17: =IFERROR(TRIM(MID(D17,SEARCH(" vs ",D17)+4,LEN(D17))),"") -> Boundaryline | I17: =IF(OR(E17="",G17=""),"",IF(AND(F17="Paid",H17="Paid"),"Both Paid",IF(AND(OR(F17="Pending",F17=""),OR(H17="Pending",H17="")),"Both Pending",IF(AND(F17="Not Applicable",H17="Not Applicable"),"Not Applicable",IF(OR(F17="Paid",H17="Paid"),"Partially Paid","Pending"))))) -> Both Pending
A18: =IF(OR('Ground Schedule'!A7="",'Ground Schedule'!J7=""),"",'Ground Schedule'!A7) | B18: =IF(A18="","",'Ground Schedule'!C7) | C18: =IF(A18="","",'Ground Schedule'!J$4) | D18: =IF(A18="","",'Ground Schedule'!J7) | E18: =IFERROR(TRIM(LEFT(D18,SEARCH(" vs ",D18)-1)),"") | G18: =IFERROR(TRIM(MID(D18,SEARCH(" vs ",D18)+4,LEN(D18))),"") | I18: =IF(OR(E18="",G18=""),"",IF(AND(F18="Paid",H18="Paid"),"Both Paid",IF(AND(OR(F18="Pending",F18=""),OR(H18="Pending",H18="")),"Both Pending",IF(AND(F18="Not Applicable",H18="Not Applicable"),"Not Applicable",IF(OR(F18="Paid",H18="Paid"),"Partially Paid","Pending")))))
A19: =IF(OR('Ground Schedule'!A8="",'Ground Schedule'!F8=""),"",'Ground Schedule'!A8) | B19: =IF(A19="","",'Ground Schedule'!C8) | C19: =IF(A19="","",'Ground Schedule'!F$4) | D19: =IF(A19="","",'Ground Schedule'!F8) | E19: =IFERROR(TRIM(LEFT(D19,SEARCH(" vs ",D19)-1)),"") | G19: =IFERROR(TRIM(MID(D19,SEARCH(" vs ",D19)+4,LEN(D19))),"") | I19: =IF(OR(E19="",G19=""),"",IF(AND(F19="Paid",H19="Paid"),"Both Paid",IF(AND(OR(F19="Pending",F19=""),OR(H19="Pending",H19="")),"Both Pending",IF(AND(F19="Not Applicable",H19="Not Applicable"),"Not Applicable",IF(OR(F19="Paid",H19="Paid"),"Partially Paid","Pending")))))
A20: =IF(OR('Ground Schedule'!A8="",'Ground Schedule'!G8=""),"",'Ground Schedule'!A8) | B20: =IF(A20="","",'Ground Schedule'!C8) | C20: =IF(A20="","",'Ground Schedule'!G$4) | D20: =IF(A20="","",'Ground Schedule'!G8) | E20: =IFERROR(TRIM(LEFT(D20,SEARCH(" vs ",D20)-1)),"") | G20: =IFERROR(TRIM(MID(D20,SEARCH(" vs ",D20)+4,LEN(D20))),"") | I20: =IF(OR(E20="",G20=""),"",IF(AND(F20="Paid",H20="Paid"),"Both Paid",IF(AND(OR(F20="Pending",F20=""),OR(H20="Pending",H20="")),"Both Pending",IF(AND(F20="Not Applicable",H20="Not Applicable"),"Not Applicable",IF(OR(F20="Paid",H20="Paid"),"Partially Paid","Pending")))))
A21: =IF(OR('Ground Schedule'!A8="",'Ground Schedule'!H8=""),"",'Ground Schedule'!A8) | B21: =IF(A21="","",'Ground Schedule'!C8) | C21: =IF(A21="","",'Ground Schedule'!H$4) | D21: =IF(A21="","",'Ground Schedule'!H8) | E21: =IFERROR(TRIM(LEFT(D21,SEARCH(" vs ",D21)-1)),"") | G21: =IFERROR(TRIM(MID(D21,SEARCH(" vs ",D21)+4,LEN(D21))),"") | I21: =IF(OR(E21="",G21=""),"",IF(AND(F21="Paid",H21="Paid"),"Both Paid",IF(AND(OR(F21="Pending",F21=""),OR(H21="Pending",H21="")),"Both Pending",IF(AND(F21="Not Applicable",H21="Not Applicable"),"Not Applicable",IF(OR(F21="Paid",H21="Paid"),"Partially Paid","Pending")))))
A22: =IF(OR('Ground Schedule'!A8="",'Ground Schedule'!I8=""),"",'Ground Schedule'!A8) | B22: =IF(A22="","",'Ground Schedule'!C8) | C22: =IF(A22="","",'Ground Schedule'!I$4) | D22: =IF(A22="","",'Ground Schedule'!I8) | E22: =IFERROR(TRIM(LEFT(D22,SEARCH(" vs ",D22)-1)),"") | G22: =IFERROR(TRIM(MID(D22,SEARCH(" vs ",D22)+4,LEN(D22))),"") | I22: =IF(OR(E22="",G22=""),"",IF(AND(F22="Paid",H22="Paid"),"Both Paid",IF(AND(OR(F22="Pending",F22=""),OR(H22="Pending",H22="")),"Both Pending",IF(AND(F22="Not Applicable",H22="Not Applicable"),"Not Applicable",IF(OR(F22="Paid",H22="Paid"),"Partially Paid","Pending")))))
A23: =IF(OR('Ground Schedule'!A8="",'Ground Schedule'!J8=""),"",'Ground Schedule'!A8) | B23: =IF(A23="","",'Ground Schedule'!C8) | C23: =IF(A23="","",'Ground Schedule'!J$4) | D23: =IF(A23="","",'Ground Schedule'!J8) | E23: =IFERROR(TRIM(LEFT(D23,SEARCH(" vs ",D23)-1)),"") | G23: =IFERROR(TRIM(MID(D23,SEARCH(" vs ",D23)+4,LEN(D23))),"") | I23: =IF(OR(E23="",G23=""),"",IF(AND(F23="Paid",H23="Paid"),"Both Paid",IF(AND(OR(F23="Pending",F23=""),OR(H23="Pending",H23="")),"Both Pending",IF(AND(F23="Not Applicable",H23="Not Applicable"),"Not Applicable",IF(OR(F23="Paid",H23="Paid"),"Partially Paid","Pending")))))
A24: =IF(OR('Ground Schedule'!A9="",'Ground Schedule'!F9=""),"",'Ground Schedule'!A9) | B24: =IF(A24="","",'Ground Schedule'!C9) | C24: =IF(A24="","",'Ground Schedule'!F$4) | D24: =IF(A24="","",'Ground Schedule'!F9) | E24: =IFERROR(TRIM(LEFT(D24,SEARCH(" vs ",D24)-1)),"") | G24: =IFERROR(TRIM(MID(D24,SEARCH(" vs ",D24)+4,LEN(D24))),"") | I24: =IF(OR(E24="",G24=""),"",IF(AND(F24="Paid",H24="Paid"),"Both Paid",IF(AND(OR(F24="Pending",F24=""),OR(H24="Pending",H24="")),"Both Pending",IF(AND(F24="Not Applicable",H24="Not Applicable"),"Not Applicable",IF(OR(F24="Paid",H24="Paid"),"Partially Paid","Pending")))))
A25: =IF(OR('Ground Schedule'!A9="",'Ground Schedule'!G9=""),"",'Ground Schedule'!A9) -> 46299 | B25: =IF(A25="","",'Ground Schedule'!C9) -> Lords of Maval | C25: =IF(A25="","",'Ground Schedule'!G$4) -> 10:30 AM Slot | D25: =IF(A25="","",'Ground Schedule'!G9) -> Titan Wolves vs Royal Strikers | E25: =IFERROR(TRIM(LEFT(D25,SEARCH(" vs ",D25)-1)),"") -> Titan Wolves | G25: =IFERROR(TRIM(MID(D25,SEARCH(" vs ",D25)+4,LEN(D25))),"") -> Royal Strikers | I25: =IF(OR(E25="",G25=""),"",IF(AND(F25="Paid",H25="Paid"),"Both Paid",IF(AND(OR(F25="Pending",F25=""),OR(H25="Pending",H25="")),"Both Pending",IF(AND(F25="Not Applicable",H25="Not Applicable"),"Not Applicable",IF(OR(F25="Paid",H25="Paid"),"Partially Paid","Pending"))))) -> Both Pending
A26: =IF(OR('Ground Schedule'!A9="",'Ground Schedule'!H9=""),"",'Ground Schedule'!A9) | B26: =IF(A26="","",'Ground Schedule'!C9) | C26: =IF(A26="","",'Ground Schedule'!H$4) | D26: =IF(A26="","",'Ground Schedule'!H9) | E26: =IFERROR(TRIM(LEFT(D26,SEARCH(" vs ",D26)-1)),"") | G26: =IFERROR(TRIM(MID(D26,SEARCH(" vs ",D26)+4,LEN(D26))),"") | I26: =IF(OR(E26="",G26=""),"",IF(AND(F26="Paid",H26="Paid"),"Both Paid",IF(AND(OR(F26="Pending",F26=""),OR(H26="Pending",H26="")),"Both Pending",IF(AND(F26="Not Applicable",H26="Not Applicable"),"Not Applicable",IF(OR(F26="Paid",H26="Paid"),"Partially Paid","Pending")))))
A27: =IF(OR('Ground Schedule'!A9="",'Ground Schedule'!I9=""),"",'Ground Schedule'!A9) -> 46299 | B27: =IF(A27="","",'Ground Schedule'!C9) -> Lords of Maval | C27: =IF(A27="","",'Ground Schedule'!I$4) -> 02:00 PM Slot | D27: =IF(A27="","",'Ground Schedule'!I9) -> Practice Match | E27: =IFERROR(TRIM(LEFT(D27,SEARCH(" vs ",D27)-1)),"") | G27: =IFERROR(TRIM(MID(D27,SEARCH(" vs ",D27)+4,LEN(D27))),"") | I27: =IF(OR(E27="",G27=""),"",IF(AND(F27="Paid",H27="Paid"),"Both Paid",IF(AND(OR(F27="Pending",F27=""),OR(H27="Pending",H27="")),"Both Pending",IF(AND(F27="Not Applicable",H27="Not Applicable"),"Not Applicable",IF(OR(F27="Paid",H27="Paid"),"Partially Paid","Pending")))))
A28: =IF(OR('Ground Schedule'!A9="",'Ground Schedule'!J9=""),"",'Ground Schedule'!A9) | B28: =IF(A28="","",'Ground Schedule'!C9) | C28: =IF(A28="","",'Ground Schedule'!J$4) | D28: =IF(A28="","",'Ground Schedule'!J9) | E28: =IFERROR(TRIM(LEFT(D28,SEARCH(" vs ",D28)-1)),"") | G28: =IFERROR(TRIM(MID(D28,SEARCH(" vs ",D28)+4,LEN(D28))),"") | I28: =IF(OR(E28="",G28=""),"",IF(AND(F28="Paid",H28="Paid"),"Both Paid",IF(AND(OR(F28="Pending",F28=""),OR(H28="Pending",H28="")),"Both Pending",IF(AND(F28="Not Applicable",H28="Not Applicable"),"Not Applicable",IF(OR(F28="Paid",H28="Paid"),"Partially Paid","Pending")))))
A29: =IF(OR('Ground Schedule'!A10="",'Ground Schedule'!F10=""),"",'Ground Schedule'!A10) | B29: =IF(A29="","",'Ground Schedule'!C10) | C29: =IF(A29="","",'Ground Schedule'!F$4) | D29: =IF(A29="","",'Ground Schedule'!F10) | E29: =IFERROR(TRIM(LEFT(D29,SEARCH(" vs ",D29)-1)),"") | G29: =IFERROR(TRIM(MID(D29,SEARCH(" vs ",D29)+4,LEN(D29))),"") | I29: =IF(OR(E29="",G29=""),"",IF(AND(F29="Paid",H29="Paid"),"Both Paid",IF(AND(OR(F29="Pending",F29=""),OR(H29="Pending",H29="")),"Both Pending",IF(AND(F29="Not Applicable",H29="Not Applicable"),"Not Applicable",IF(OR(F29="Paid",H29="Paid"),"Partially Paid","Pending")))))
A30: =IF(OR('Ground Schedule'!A10="",'Ground Schedule'!G10=""),"",'Ground Schedule'!A10) -> 46305 | B30: =IF(A30="","",'Ground Schedule'!C10) -> AK Club DY Patil Ground | C30: =IF(A30="","",'Ground Schedule'!G$4) -> 10:30 AM Slot | D30: =IF(A30="","",'Ground Schedule'!G10) -> Phoenix Risers vs Overtime Hitters | E30: =IFERROR(TRIM(LEFT(D30,SEARCH(" vs ",D30)-1)),"") -> Phoenix Risers | G30: =IFERROR(TRIM(MID(D30,SEARCH(" vs ",D30)+4,LEN(D30))),"") -> Overtime Hitters | I30: =IF(OR(E30="",G30=""),"",IF(AND(F30="Paid",H30="Paid"),"Both Paid",IF(AND(OR(F30="Pending",F30=""),OR(H30="Pending",H30="")),"Both Pending",IF(AND(F30="Not Applicable",H30="Not Applicable"),"Not Applicable",IF(OR(F30="Paid",H30="Paid"),"Partially Paid","Pending"))))) -> Both Pending
A31: =IF(OR('Ground Schedule'!A10="",'Ground Schedule'!H10=""),"",'Ground Schedule'!A10) | B31: =IF(A31="","",'Ground Schedule'!C10) | C31: =IF(A31="","",'Ground Schedule'!H$4) | D31: =IF(A31="","",'Ground Schedule'!H10) | E31: =IFERROR(TRIM(LEFT(D31,SEARCH(" vs ",D31)-1)),"") | G31: =IFERROR(TRIM(MID(D31,SEARCH(" vs ",D31)+4,LEN(D31))),"") | I31: =IF(OR(E31="",G31=""),"",IF(AND(F31="Paid",H31="Paid"),"Both Paid",IF(AND(OR(F31="Pending",F31=""),OR(H31="Pending",H31="")),"Both Pending",IF(AND(F31="Not Applicable",H31="Not Applicable"),"Not Applicable",IF(OR(F31="Paid",H31="Paid"),"Partially Paid","Pending")))))
A32: =IF(OR('Ground Schedule'!A10="",'Ground Schedule'!I10=""),"",'Ground Schedule'!A10) -> 46305 | B32: =IF(A32="","",'Ground Schedule'!C10) -> AK Club DY Patil Ground | C32: =IF(A32="","",'Ground Schedule'!I$4) -> 02:00 PM Slot | D32: =IF(A32="","",'Ground Schedule'!I10) -> Batboys vs Boundary Line | E32: =IFERROR(TRIM(LEFT(D32,SEARCH(" vs ",D32)-1)),"") -> Batboys | G32: =IFERROR(TRIM(MID(D32,SEARCH(" vs ",D32)+4,LEN(D32))),"") -> Boundary Line | I32: =IF(OR(E32="",G32=""),"",IF(AND(F32="Paid",H32="Paid"),"Both Paid",IF(AND(OR(F32="Pending",F32=""),OR(H32="Pending",H32="")),"Both Pending",IF(AND(F32="Not Applicable",H32="Not Applicable"),"Not Applicable",IF(OR(F32="Paid",H32="Paid"),"Partially Paid","Pending"))))) -> Both Pending
A33: =IF(OR('Ground Schedule'!A10="",'Ground Schedule'!J10=""),"",'Ground Schedule'!A10) | B33: =IF(A33="","",'Ground Schedule'!C10) | C33: =IF(A33="","",'Ground Schedule'!J$4) | D33: =IF(A33="","",'Ground Schedule'!J10) | E33: =IFERROR(TRIM(LEFT(D33,SEARCH(" vs ",D33)-1)),"") | G33: =IFERROR(TRIM(MID(D33,SEARCH(" vs ",D33)+4,LEN(D33))),"") | I33: =IF(OR(E33="",G33=""),"",IF(AND(F33="Paid",H33="Paid"),"Both Paid",IF(AND(OR(F33="Pending",F33=""),OR(H33="Pending",H33="")),"Both Pending",IF(AND(F33="Not Applicable",H33="Not Applicable"),"Not Applicable",IF(OR(F33="Paid",H33="Paid"),"Partially Paid","Pending")))))
A34: =IF(OR('Ground Schedule'!A11="",'Ground Schedule'!F11=""),"",'Ground Schedule'!A11) | B34: =IF(A34="","",'Ground Schedule'!C11) | C34: =IF(A34="","",'Ground Schedule'!F$4) | D34: =IF(A34="","",'Ground Schedule'!F11) | E34: =IFERROR(TRIM(LEFT(D34,SEARCH(" vs ",D34)-1)),"") | G34: =IFERROR(TRIM(MID(D34,SEARCH(" vs ",D34)+4,LEN(D34))),"") | I34: =IF(OR(E34="",G34=""),"",IF(AND(F34="Paid",H34="Paid"),"Both Paid",IF(AND(OR(F34="Pending",F34=""),OR(H34="Pending",H34="")),"Both Pending",IF(AND(F34="Not Applicable",H34="Not Applicable"),"Not Applicable",IF(OR(F34="Paid",H34="Paid"),"Partially Paid","Pending")))))
A35: =IF(OR('Ground Schedule'!A11="",'Ground Schedule'!G11=""),"",'Ground Schedule'!A11) -> 46305 | B35: =IF(A35="","",'Ground Schedule'!C11) -> MCG Ground | C35: =IF(A35="","",'Ground Schedule'!G$4) -> 10:30 AM Slot | D35: =IF(A35="","",'Ground Schedule'!G11) -> Bharam 11 vs Scoring Swords | E35: =IFERROR(TRIM(LEFT(D35,SEARCH(" vs ",D35)-1)),"") -> Bharam 11 | G35: =IFERROR(TRIM(MID(D35,SEARCH(" vs ",D35)+4,LEN(D35))),"") -> Scoring Swords | I35: =IF(OR(E35="",G35=""),"",IF(AND(F35="Paid",H35="Paid"),"Both Paid",IF(AND(OR(F35="Pending",F35=""),OR(H35="Pending",H35="")),"Both Pending",IF(AND(F35="Not Applicable",H35="Not Applicable"),"Not Applicable",IF(OR(F35="Paid",H35="Paid"),"Partially Paid","Pending"))))) -> Both Pending
A36: =IF(OR('Ground Schedule'!A11="",'Ground Schedule'!H11=""),"",'Ground Schedule'!A11) | B36: =IF(A36="","",'Ground Schedule'!C11) | C36: =IF(A36="","",'Ground Schedule'!H$4) | D36: =IF(A36="","",'Ground Schedule'!H11) | E36: =IFERROR(TRIM(LEFT(D36,SEARCH(" vs ",D36)-1)),"") | G36: =IFERROR(TRIM(MID(D36,SEARCH(" vs ",D36)+4,LEN(D36))),"") | I36: =IF(OR(E36="",G36=""),"",IF(AND(F36="Paid",H36="Paid"),"Both Paid",IF(AND(OR(F36="Pending",F36=""),OR(H36="Pending",H36="")),"Both Pending",IF(AND(F36="Not Applicable",H36="Not Applicable"),"Not Applicable",IF(OR(F36="Paid",H36="Paid"),"Partially Paid","Pending")))))
A37: =IF(OR('Ground Schedule'!A11="",'Ground Schedule'!I11=""),"",'Ground Schedule'!A11) | B37: =IF(A37="","",'Ground Schedule'!C11) | C37: =IF(A37="","",'Ground Schedule'!I$4) | D37: =IF(A37="","",'Ground Schedule'!I11) | E37: =IFERROR(TRIM(LEFT(D37,SEARCH(" vs ",D37)-1)),"") | G37: =IFERROR(TRIM(MID(D37,SEARCH(" vs ",D37)+4,LEN(D37))),"") | I37: =IF(OR(E37="",G37=""),"",IF(AND(F37="Paid",H37="Paid"),"Both Paid",IF(AND(OR(F37="Pending",F37=""),OR(H37="Pending",H37="")),"Both Pending",IF(AND(F37="Not Applicable",H37="Not Applicable"),"Not Applicable",IF(OR(F37="Paid",H37="Paid"),"Partially Paid","Pending")))))
A38: =IF(OR('Ground Schedule'!A11="",'Ground Schedule'!J11=""),"",'Ground Schedule'!A11) | B38: =IF(A38="","",'Ground Schedule'!C11) | C38: =IF(A38="","",'Ground Schedule'!J$4) | D38: =IF(A38="","",'Ground Schedule'!J11) | E38: =IFERROR(TRIM(LEFT(D38,SEARCH(" vs ",D38)-1)),"") | G38: =IFERROR(TRIM(MID(D38,SEARCH(" vs ",D38)+4,LEN(D38))),"") | I38: =IF(OR(E38="",G38=""),"",IF(AND(F38="Paid",H38="Paid"),"Both Paid",IF(AND(OR(F38="Pending",F38=""),OR(H38="Pending",H38="")),"Both Pending",IF(AND(F38="Not Applicable",H38="Not Applicable"),"Not Applicable",IF(OR(F38="Paid",H38="Paid"),"Partially Paid","Pending")))))
A39: =IF(OR('Ground Schedule'!A12="",'Ground Schedule'!F12=""),"",'Ground Schedule'!A12) | B39: =IF(A39="","",'Ground Schedule'!C12) | C39: =IF(A39="","",'Ground Schedule'!F$4) | D39: =IF(A39="","",'Ground Schedule'!F12) | E39: =IFERROR(TRIM(LEFT(D39,SEARCH(" vs ",D39)-1)),"") | G39: =IFERROR(TRIM(MID(D39,SEARCH(" vs ",D39)+4,LEN(D39))),"") | I39: =IF(OR(E39="",G39=""),"",IF(AND(F39="Paid",H39="Paid"),"Both Paid",IF(AND(OR(F39="Pending",F39=""),OR(H39="Pending",H39="")),"Both Pending",IF(AND(F39="Not Applicable",H39="Not Applicable"),"Not Applicable",IF(OR(F39="Paid",H39="Paid"),"Partially Paid","Pending")))))
A40: =IF(OR('Ground Schedule'!A12="",'Ground Schedule'!G12=""),"",'Ground Schedule'!A12) -> 46306 | B40: =IF(A40="","",'Ground Schedule'!C12) -> AK Club DY Patil Ground | C40: =IF(A40="","",'Ground Schedule'!G$4) -> 10:30 AM Slot | D40: =IF(A40="","",'Ground Schedule'!G12) -> Decisive 11 vs Bravebulls | E40: =IFERROR(TRIM(LEFT(D40,SEARCH(" vs ",D40)-1)),"") -> Decisive 11 | G40: =IFERROR(TRIM(MID(D40,SEARCH(" vs ",D40)+4,LEN(D40))),"") -> Bravebulls | I40: =IF(OR(E40="",G40=""),"",IF(AND(F40="Paid",H40="Paid"),"Both Paid",IF(AND(OR(F40="Pending",F40=""),OR(H40="Pending",H40="")),"Both Pending",IF(AND(F40="Not Applicable",H40="Not Applicable"),"Not Applicable",IF(OR(F40="Paid",H40="Paid"),"Partially Paid","Pending"))))) -> Both Pending
...

Sheet Read Me
A1: DK Cricket Ops — How to use this workbook
A2: 1. Ground Schedule keeps Date, Day and Ground frozen while you scroll across the slots.
A3: 2. Keep tennis advance bookings in the morning tennis slot; use leather slots for practice or tournament matches.
A4: 3. Enter each fixture in the appropriate time-slot cell. Keep the ground and booking notes in the same row.
A5: 4. Use Ground Status to mark Booked, Scheduled, Available or Completed.
A6: 5. In the last column, enter the name(s) of teams whose payments have arrived. Leave it blank while payment is pending.
A7: 6. Tournament Teams has a separate team list for each tournament based on the screenshots provided. Verify spellings and add/remove teams as needed.
A8: 7. The workbook is a manual tracker and does not sync with CricHeroes or UPI automatically.
A9: 8. Round Robin Fixtures contains every unique league pairing once per tournament; enter date, ground and slot as you schedule matches.
A10: 9. Mark a fixture Completed after the match. Team A and Team B payments are tracked separately as Pending/Paid.
A11: Leather Payment Tracker | B11: Enter one match per row; mark Team A and Team B independently as Pending/Paid/Not Applicable. Paid turns green, Pending orange, and overall status updates automatically.
A12: Ground schedule correction | B12: Weekend dates are restored from the original transcription. Each Saturday/Sunday has 3 rows. Entries whose ground was blank in the photo are labeled Ground TBC instead of guessing. Strong contrasting colours distinguish ground, tennis slots, leather slots, and booking status.

Sheet Tournament Lists
A1: Tournament Name | B1: Fixture / Team Names visible in photo
A2: Winter Championship | B2: Team Aristo vs Scoring Swords
A3: Winter Championship | B3: Hitman Sports vs Boundaryline
A4: Winter Championship | B4: Batboys vs Boundary Line
A5: Winter Championship | B5: Boundary Line vs Royals 11
A6: CCL | B6: No fixture names visible in photo
A7: Pink County Cup | B7: No fixture names visible in photo
A8: Corporate Strikers | B8: No fixture names visible in photo
A9: AK Club Quadrangular | B9: No fixture names visible in photo

Sheet Tournament Teams
A1: DK CRICKET OPS — TOURNAMENT TEAM DIRECTORY
A2: Teams below are taken from your screenshots. Review any spelling or tournament membership that needs correction.
A3: CCL Pune (Corporate T20 Champions League) | B3: Winter Championship | C3: Pink County Cup | D3: Corporate Strikers | E3: AK Club Quadrangular Cup
A4: Batboys | B4: Batboys | C4: Batboys | D4: Batboys | E4: Deccan Shiledars
A5: Boundary Line Elite - XI | B5: Boundary Line Elite - XI | C5: Black Caps 11 | D5: BR Bulls | E5: Phoenix Risers
A6: HITMAN SPORTS S4 | B6: HITMAN SPORTS S4 | C6: Shivas Smashers | D6: Pune Titans | E6: Team Aristo
A7: Royals XI | B7: Royals XI | C7: Topguns Cricket Club | D7: Royal Strikers -2024 | E7: Titan Wolves
A8: Scoring Swords (Pune) | B8: Scoring Swords (Pune) | D8: Royals XI
A9: Team Aristo | B9: Team Aristo | D9: S.I Warriors
A10: Top Gun Mavericks | B10: Top Gun Mavericks | D10: STALLION STRIKERS

Sheet Round Robin Fixtures
A1: DK CRICKET OPS — ROUND ROBIN FIXTURES
A2: Every team pair appears once per tournament. Status is editable: Completed / Scheduled / To Be Scheduled / Cancelled.
A3: Tournament | B3: Round | C3: Match No. | D3: Team A | E3: Team B | F3: Fixture | G3: Date | H3: Ground | I3: Time Slot | J3: Status | K3: Team A Payment | L3: Team B Payment | M3: Notes
A4: CCL Pune (Corporate T20 Champions League) | B4: 1 | C4: 1 | D4: Boundary Line Elite - XI | E4: Top Gun Mavericks | F4: Boundary Line Elite - XI vs Top Gun Mavericks | J4: To Be Scheduled | K4: Pending | L4: Pending
A5: CCL Pune (Corporate T20 Champions League) | B5: 1 | C5: 2 | D5: HITMAN SPORTS S4 | E5: Team Aristo | F5: HITMAN SPORTS S4 vs Team Aristo | J5: To Be Scheduled | K5: Pending | L5: Pending
A6: CCL Pune (Corporate T20 Champions League) | B6: 1 | C6: 3 | D6: Royals XI | E6: Scoring Swords (Pune) | F6: Royals XI vs Scoring Swords (Pune) | J6: To Be Scheduled | K6: Pending | L6: Pending
A7: CCL Pune (Corporate T20 Champions League) | B7: 2 | C7: 4 | D7: Batboys | E7: Top Gun Mavericks | F7: Batboys vs Top Gun Mavericks | J7: To Be Scheduled | K7: Pending | L7: Pending
A8: CCL Pune (Corporate T20 Champions League) | B8: 2 | C8: 5 | D8: Boundary Line Elite - XI | E8: Scoring Swords (Pune) | F8: Boundary Line Elite - XI vs Scoring Swords (Pune) | J8: To Be Scheduled | K8: Pending | L8: Pending
A9: CCL Pune (Corporate T20 Champions League) | B9: 2 | C9: 6 | D9: HITMAN SPORTS S4 | E9: Royals XI | F9: HITMAN SPORTS S4 vs Royals XI | J9: To Be Scheduled | K9: Pending | L9: Pending
A10: CCL Pune (Corporate T20 Champions League) | B10: 3 | C10: 7 | D10: Batboys | E10: Team Aristo | F10: Batboys vs Team Aristo | J10: To Be Scheduled | K10: Pending | L10: Pending
A11: CCL Pune (Corporate T20 Champions League) | B11: 3 | C11: 8 | D11: Top Gun Mavericks | E11: Scoring Swords (Pune) | F11: Top Gun Mavericks vs Scoring Swords (Pune) | J11: To Be Scheduled | K11: Pending | L11: Pending
A12: CCL Pune (Corporate T20 Champions League) | B12: 3 | C12: 9 | D12: Boundary Line Elite - XI | E12: HITMAN SPORTS S4 | F12: Boundary Line Elite - XI vs HITMAN SPORTS S4 | J12: To Be Scheduled | K12: Pending | L12: Pending
A13: CCL Pune (Corporate T20 Champions League) | B13: 4 | C13: 10 | D13: Batboys | E13: Scoring Swords (Pune) | F13: Batboys vs Scoring Swords (Pune) | J13: To Be Scheduled | K13: Pending | L13: Pending
A14: CCL Pune (Corporate T20 Champions League) | B14: 4 | C14: 11 | D14: Team Aristo | E14: Royals XI | F14: Team Aristo vs Royals XI | J14: To Be Scheduled | K14: Pending | L14: Pending
A15: CCL Pune (Corporate T20 Champions League) | B15: 4 | C15: 12 | D15: Top Gun Mavericks | E15: HITMAN SPORTS S4 | F15: Top Gun Mavericks vs HITMAN SPORTS S4 | J15: To Be Scheduled | K15: Pending | L15: Pending
... A78: AK Club Quadrangular Cup | B78: 3 | C78: 75 | D78: Team Aristo | E78: Titan Wolves | F78: Team Aristo vs Titan Wolves | J78: To Be Scheduled | K78: Pending | L78: Pending

Sheet Previous Payment Tracker
A1: DK CRICKET OPS — LEATHER MATCH PAYMENT TRACKER
A2: Track each leather match here. Team A and Team B payments are separate because each team pays independently by GPay. Select Pending / Paid / Not Applicable from each dropdown.
A3: Match Date | B3: Ground | C3: Time Slot | D3: Tournament | E3: Team A | F3: Team A Payment | G3: Team B | H3: Team B Payment | I3: Overall Payment Status | J3: Payment Notes
A4: 2026-10-02 | B4: AK Club DY Patil Ground | C4: 10:30 AM | D4: CCL | E4: Batboys | F4: Pending | G4: Overtime Hitters | H4: Pending | I4: =IF(COUNTA(E4,G4)=0,"",IF(AND(OR(F4="Paid",F4="Not Applicable"),OR(H4="Paid",H4="Not Applicable")),"Both Paid",IF(AND(F4="Pending",H4="Pending"),"Both Pending","Partially Paid"))) -> Both Pending
A5: 2026-10-03 | B5: MCG Ground | C5: 10:30 AM | D5: CCL | E5: Team Aristo | F5: Pending | G5: Scoring Swords (Pune) | H5: Pending | I5: =IF(COUNTA(E5,G5)=0,"",IF(AND(OR(F5="Paid",F5="Not Applicable"),OR(H5="Paid",H5="Not Applicable")),"Both Paid",IF(AND(F5="Pending",H5="Pending"),"Both Pending","Partially Paid"))) -> Both Pending
A6: 2026-10-03 | B6: MCG Ground | C6: 02:00 PM | D6: CCL | E6: HITMAN SPORTS S4 | F6: Pending | G6: Boundary Line Elite - XI | H6: Pending | I6: =IF(COUNTA(E6,G6)=0,"",IF(AND(OR(F6="Paid",F6="Not Applicable"),OR(H6="Paid",H6="Not Applicable")),"Both Paid",IF(AND(F6="Pending",H6="Pending"),"Both Pending","Partially Paid"))) -> Both Pending
A7: 2026-10-04 | B7: MCG Ground | C7: 10:30 AM | D7: CCL | E7: Titan Wolves | F7: Pending | G7: Royal Strikers -2024 | H7: Pending | I7: =IF(COUNTA(E7,G7)=0,"",IF(AND(OR(F7="Paid",F7="Not Applicable"),OR(H7="Paid",H7="Not Applicable")),"Both Paid",IF(AND(F7="Pending",H7="Pending"),"Both Pending","Partially Paid"))) -> Both Pending
A8: 2026-10-10 | B8: AK Club DY Patil Ground | C8: 10:30 AM | D8: CCL | E8: Phoenix Risers | F8: Pending | G8: Titan Wolves | H8: Pending | I8: =IF(COUNTA(E8,G8)=0,"",IF(AND(OR(F8="Paid",F8="Not Applicable"),OR(H8="Paid",H8="Not Applicable")),"Both Paid",IF(AND(F8="Pending",H8="Pending"),"Both Pending","Partially Paid"))) -> Both Pending | J8: Previously marked completed in schedule; confirm if payments were received.
A9: 2026-10-10 | B9: AK Club DY Patil Ground | C9: 02:00 PM | D9: CCL | E9: Batboys | F9: Pending | G9: Boundary Line Elite - XI | H9: Pending | I9: =IF(COUNTA(E9,G9)=0,"",IF(AND(OR(F9="Paid",F9="Not Applicable"),OR(H9="Paid",H9="Not Applicable")),"Both Paid",IF(AND(F9="Pending",H9="Pending"),"Both Pending","Partially Paid"))) -> Both Pending
A10: 2026-10-10 | B10: MCG Ground | C10: 10:30 AM | D10: CCL | E10: Team Aristo | F10: Pending | G10: Scoring Swords (Pune) | H10: Pending | I10: =IF(COUNTA(E10,G10)=0,"",IF(AND(OR(F10="Paid",F10="Not Applicable"),OR(H10="Paid",H10="Not Applicable")),"Both Paid",IF(AND(F10="Pending",H10="Pending"),"Both Pending","Partially Paid"))) -> Both Pending | J10: Previously marked completed in schedule; confirm if payments were received.
A11: 2026-10-11 | B11: AK Club DY Patil Ground | C11: 10:30 AM | D11: CCL | E11: Bharam 11 | F11: Pending | G11: Scoring Swords (Pune) | H11: Pending | I11: =IF(COUNTA(E11,G11)=0,"",IF(AND(OR(F11="Paid",F11="Not Applicable"),OR(H11="Paid",H11="Not Applicable")),"Both Paid",IF(AND(F11="Pending",H11="Pending"),"Both Pending","Partially Paid"))) -> Both Pending
A12: 2026-10-11 | B12: MCG Ground | C12: 10:30 AM | D12: CCL | E12: Titan Wolves | F12: Pending | G12: Royal Strikers -2024 | H12: Pending | I12: =IF(COUNTA(E12,G12)=0,"",IF(AND(OR(F12="Paid",F12="Not Applicable"),OR(H12="Paid",H12="Not Applicable")),"Both Paid",IF(AND(F12="Pending",H12="Pending"),"Both Pending","Partially Paid"))) -> Both Pending
A13: 2026-10-11 | B13: Lords of Maval | C13: 10:30 AM | D13: CCL | E13: Microland | F13: Pending | G13: Strikeforge | H13: Pending | I13: =IF(COUNTA(E13,G13)=0,"",IF(AND(OR(F13="Paid",F13="Not Applicable"),OR(H13="Paid",H13="Not Applicable")),"Both Paid",IF(AND(F13="Pending",H13="Pending"),"Both Pending","Partially Paid"))) -> Both Pending
A14: 2026-10-11 | B14: MCG Ground | C14: 12:00 PM | D14: CCL | E14: Sangha University | F14: Pending | G14: Practice Match | H14: Pending | I14: =IF(COUNTA(E14,G14)=0,"",IF(AND(OR(F14="Paid",F14="Not Applicable"),OR(H14="Paid",H14="Not Applicable")),"Both Paid",IF(AND(F14="Pending",H14="Pending"),"Both Pending","Partially Paid"))) -> Both Pending | J14: Practice match — use if payment is applicable.
A15: 2026-10-17 | B15: AK Club DY Patil Ground | C15: 10:30 AM | D15: CCL | E15: Strikeforge | F15: Pending | G15: Township (P) | H15: Pending | I15: =IF(COUNTA(E15,G15)=0,"",IF(AND(OR(F15="Paid",F15="Not Applicable"),OR(H15="Paid",H15="Not Applicable")),"Both Paid",IF(AND(F15="Pending",H15="Pending"),"Both Pending","Partially Paid"))) -> Both Pending | J15: Upcoming match; track each team payment separately.
A16: 2026-10-17 | B16: AK Club DY Patil Ground | C16: 02:00 PM | D16: Winter Championship | E16: Top Gun Mavericks | F16: Pending | G16: Scoring Swords (Pune) | H16: Pending | I16: =IF(COUNTA(E16,G16)=0,"",IF(AND(OR(F16="Paid",F16="Not Applicable"),OR(H16="Paid",H16="Not Applicable")),"Both Paid",IF(AND(F16="Pending",H16="Pending"),"Both Pending","Partially Paid"))) -> Both Pending
A17: 2026-10-18 | B17: AK Club DY Patil Ground | C17: 10:30 AM | D17: CCL | E17: S.I Warriors | F17: Pending | G17: Royal Strikers -2024 | H17: Pending | I17: =IF(COUNTA(E17,G17)=0,"",IF(AND(OR(F17="Paid",F17="Not Applicable"),OR(H17="Paid",H17="Not Applicable")),"Both Paid",IF(AND(F17="Pending",H17="Pending"),"Both Pending","Partially Paid"))) -> Both Pending
A18: 2026-10-18 | B18: AK Club DY Patil Ground | C18: 02:00 PM | D18: Winter Championship | E18: Team Aristo | F18: Pending | G18: Boundary Line Elite - XI | H18: Pending | I18: =IF(COUNTA(E18,G18)=0,"",IF(AND(OR(F18="Paid",F18="Not Applicable"),OR(H18="Paid",H18="Not Applicable")),"Both Paid",IF(AND(F18="Pending",H18="Pending"),"Both Pending","Partially Paid"))) -> Both Pending
F19: Pending | H19: Pending | I19: =IF(COUNTA(E19,G19)=0,"",IF(AND(OR(F19="Paid",F19="Not Applicable"),OR(H19="Paid",H19="Not Applicable")),"Both Paid",IF(AND(F19="Pending",H19="Pending"),"Both Pending","Partially Paid")))
F20: Pending | H20: Pending | I20: =IF(COUNTA(E20,G20)=0,"",IF(AND(OR(F20="Paid",F20="Not Applicable"),OR(H20="Paid",H20="Not Applicable")),"Both Paid",IF(AND(F20="Pending",H20="Pending"),"Both Pending","Partially Paid")))
F21: Pending | H21: Pending | I21: =IF(COUNTA(E21,G21)=0,"",IF(AND(OR(F21="Paid",F21="Not Applicable"),OR(H21="Paid",H21="Not Applicable")),"Both Paid",IF(AND(F21="Pending",H21="Pending"),"Both Pending","Partially Paid")))
F22: Pending | H22: Pending | I22: =IF(COUNTA(E22,G22)=0,"",IF(AND(OR(F22="Paid",F22="Not Applicable"),OR(H22="Paid",H22="Not Applicable")),"Both Paid",IF(AND(F22="Pending",H22="Pending"),"Both Pending","Partially Paid")))
F23: Pending | H23: Pending | I23: =IF(COUNTA(E23,G23)=0,"",IF(AND(OR(F23="Paid",F23="Not Applicable"),OR(H23="Paid",H23="Not Applicable")),"Both Paid",IF(AND(F23="Pending",H23="Pending"),"Both Pending","Partially Paid")))
F24: Pending | H24: Pending | I24: =IF(COUNTA(E24,G24)=0,"",IF(AND(OR(F24="Paid",F24="Not Applicable"),OR(H24="Paid",H24="Not Applicable")),"Both Paid",IF(AND(F24="Pending",H24="Pending"),"Both Pending","Partially Paid")))
F25: Pending | H25: Pending | I25: =IF(COUNTA(E25,G25)=0,"",IF(AND(OR(F25="Paid",F25="Not Applicable"),OR(H25="Paid",H25="Not Applicable")),"Both Paid",IF(AND(F25="Pending",H25="Pending"),"Both Pending","Partially Paid")))
F26: Pending | H26: Pending | I26: =IF(COUNTA(E26,G26)=0,"",IF(AND(OR(F26="Paid",F26="Not Applicable"),OR(H26="Paid",H26="Not Applicable")),"Both Paid",IF(AND(F26="Pending",H26="Pending"),"Both Pending","Partially Paid")))
F27: Pending | H27: Pending | I27: =IF(COUNTA(E27,G27)=0,"",IF(AND(OR(F27="Paid",F27="Not Applicable"),OR(H27="Paid",H27="Not Applicable")),"Both Paid",IF(AND(F27="Pending",H27="Pending"),"Both Pending","Partially Paid")))
F28: Pending | H28: Pending | I28: =IF(COUNTA(E28,G28)=0,"",IF(AND(OR(F28="Paid",F28="Not Applicable"),OR(H28="Paid",H28="Not Applicable")),"Both Paid",IF(AND(F28="Pending",H28="Pending"),"Both Pending","Partially Paid")))
F29: Pending | H29: Pending | I29: =IF(COUNTA(E29,G29)=0,"",IF(AND(OR(F29="Paid",F29="Not Applicable"),OR(H29="Paid",H29="Not Applicable")),"Both Paid",IF(AND(F29="Pending",H29="Pending"),"Both Pending","Partially Paid")))
F30: Pending | H30: Pending | I30: =IF(COUNTA(E30,G30)=0,"",IF(AND(OR(F30="Paid",F30="Not Applicable"),OR(H30="Paid",H30="Not Applicable")),"Both Paid",IF(AND(F30="Pending",H30="Pending"),"Both Pending","Partially Paid")))
... F120: Pending | H120: Pending | I120: =IF(COUNTA(E120,G120)=0,"",IF(AND(OR(F120="Paid",F120="Not Applicable"),OR(H120="Paid",H120="Not Applicable")),"Both Paid",IF(AND(F120="Pending",H120="Pending"),"Both Pending","Partially Paid")))
